<?xml version="1.0" encoding="utf-8"?>
<!-- This URDF was automatically created by SolidWorks to URDF Exporter! Originally created by
Stephen Brawner (brawner@gmail.com) 
     Commit Version: 1.6.0-4-g7f85cfe  Build Version: 1.6.7995.38578
     For more information, please see http://wiki.ros.org/sw_urdf_exporter -->
<robot xmlns:xacro="http://wiki.ros.org/xacro">
  <xacro:macro name="ar_gripper" params="
    tf_prefix
    parent
  ">
    <joint name="${tf_prefix}gripper_base_joint" type="fixed">
      <origin xyz="0.0 0.0 0.0" rpy="-1.5708 0.0 0.0" />
      <parent link="${parent}" />
      <child link="${tf_prefix}gripper_base_link" />
    </joint>

    <link
      name="${tf_prefix}gripper_base_link">
      <inertial>
        <origin
          xyz="0.000218865638025569 -5.75810071732045E-05 0.0188189080442559"
          rpy="0 0 0" />
        <mass
          value="0.0779213197542101" />
        <inertia
          ixx="1.27018244320936E-05"
          ixy="-1.98293669536147E-07"
          ixz="-2.58632439119383E-07"
          iyy="2.84792796640278E-05"
          iyz="-4.25276765641554E-07"
          izz="3.57075748419373E-05" />
      </inertial>
      <visual>
        <origin
          xyz="0 0 0"
          rpy="0 0 0" />
        <geometry>
          <mesh
            filename="file://$(find annin_ar4_description)/meshes/ar4_gripper/gripper_base_link.stl" />
        </geometry>
        <material
          name="">
          <color
            rgba="0.792156862745098 0.819607843137255 0.933333333333333 1" />
        </material>
      </visual>
      <collision>
        <origin
          xyz="0 0 0"
          rpy="0 0 0" />
        <geometry>
          <mesh
            filename="file://$(find annin_ar4_description)/meshes/ar4_gripper/gripper_base_link.stl" />
        </geometry>
      </collision>
    </link>
    <link name="${tf_prefix}gripper_jaw1_link">
      <inertial>
        <origin
          xyz="0.0068393 0.0018263 -0.0052235"
          rpy="0 0 0" />
        <mass
          value="0.0080032" />
        <inertia
          ixx="7.6628E-07"
          ixy="2.1048E-07"
          ixz="4.3688E-09"
          iyy="1.0775E-06"
          iyz="-7.4587E-08"
          izz="1.3907E-06" />
      </inertial>
      <visual>
        <origin
          xyz="0 0 0"
          rpy="0 0 0" />
        <geometry>
          <mesh
            filename="file://$(find annin_ar4_description)/meshes/ar4_gripper/gripper_jaw1_link.stl" />

        </geometry>
        <material
          name="">
          <color
            rgba="1 1 1 1" />
        </material>
      </visual>
      <collision>
        <origin
          xyz="0 0 0"
          rpy="0 0 0" />
        <geometry>
          <mesh
            filename="file://$(find annin_ar4_description)/meshes/ar4_gripper/gripper_jaw1_link.stl" />

        </geometry>
      </collision>
    </link>

    <link name="${tf_prefix}gripper_jaw2_link">
      <inertial>
        <origin
          xyz="0.0068393 0.0018263 -0.0052235"
          rpy="0 0 0" />
        <mass
          value="0.0080032" />
        <inertia
          ixx="7.6628E-07"
          ixy="2.1048E-07"
          ixz="4.3688E-09"
          iyy="1.0775E-06"
          iyz="-7.4587E-08"
          izz="1.3907E-06" />
      </inertial>
      <visual>
        <origin
          xyz="0 0 0"
          rpy="0 0 0" />
        <geometry>
          <mesh
            filename="file://$(find annin_ar4_description)/meshes/ar4_gripper/gripper_jaw2_link.stl" />

        </geometry>
        <material
          name="">
          <color
            rgba="1 1 1 1" />
        </material>
      </visual>
      <collision>
        <origin
          xyz="0 0 0"
          rpy="0 0 0" />
        <geometry>
          <mesh
            filename="file://$(find annin_ar4_description)/meshes/ar4_gripper/gripper_jaw2_link.stl" />

        </geometry>
      </collision>
    </link>

    <joint name="${tf_prefix}gripper_jaw1_joint" type="prismatic">
      <origin
        xyz="0.014 -0.0029 0.001"
        rpy="1.5708 0 0 " />
      <parent
        link="${tf_prefix}gripper_base_link" />
      <child
        link="${tf_prefix}gripper_jaw1_link" />
      <axis
        xyz="-1 0 0" />
      <limit
        lower="0"
        upper="0.015"
        effort="1000"
        velocity="1.0" />
    </joint>


    <joint name="${tf_prefix}gripper_jaw2_joint" type="prismatic">
      <origin
        xyz="-0.014 -0.0029 0.001"
        rpy="1.5708 0 0" />
      <parent
        link="${tf_prefix}gripper_base_link" />
      <child
        link="${tf_prefix}gripper_jaw2_link" />
      <axis
        xyz="1 0 0" />
      <limit
        lower="0"
        upper="0.015"
        effort="1000"
        velocity="1.0" />
    </joint>
  </xacro:macro>
</robot>